Workbook

Sheet Tabelle1
A1: Block | B1: Frage Nr. | D1: Frage | E1: mögliche Antworten | F1: Anzahl der Antworten | G1: Antwortart | H1: Antwortart | I1: A1 | J1: nach A1 | K1: A2 | L1: nach A2 | M1: A3 | N1: nach A3 | O1: A4 | P1: nach A4 | Q1: A5 | R1: nach A5 | S1: A6 | T1: nach A6
A2: Vorversicherung | B2: 1 | C2: ja | D2: Wie sind sie zurzeit krankenversichert? | E2: =I2&IF(K2="","",";"&K2)&IF(M2="","",";"&M2)&IF(O2="","",";"&O2)&IF(Q2="","",";"&Q2)&IF(T2="","",";"&T2) | F2: =IF(I2="",0,1)+IF(K2="",0,1)+IF(M2="",0,1)+IF(O2="",0,1)+IF(Q2="",0,1)+IF(S2="",0,1) | G2: Button | H2: one Choice | I2: GKV | J2: V200 | K2: PKV | L2: V200 | M2: ausländische KV | N2: V200 | O2: unversichert | P2: U1 | Q2: anderweitig | R2: V200 | S2: ungeklärter Status | T2: U1
A3: Vorversicherung | B3: V200 | D3: Waren Sie in den letzten fünf Jahren in einer deutschen GKV versichert | E3: =I3&IF(K3="","",";"&K3)&IF(M3="","",";"&M3)&IF(O3="","",";"&O3)&IF(Q3="","",";"&Q3)&IF(T3="","",";"&T3) | F3: =IF(I3="",0,1)+IF(K3="",0,1)+IF(M3="",0,1)+IF(O3="",0,1)+IF(Q3="",0,1)+IF(S3="",0,1) | G3: Button | H3: one Choice | I3: ja | J3: V300 | K3: nein | L3: V300
A4: Vorversicherung | B4: V300 | C4: ja | D4: Waren Sie in den letzten fünf Jahren in einer ausländischen innerhalb der EU, der Schweiz, Norwegen, Grosss-Britanien, Ex Jugoslawien GKV versichert | E4: =I4&IF(K4="","",";"&K4)&IF(M4="","",";"&M4)&IF(O4="","",";"&O4)&IF(Q4="","",";"&Q4)&IF(T4="","",";"&T4) | F4: =IF(I4="",0,1)+IF(K4="",0,1)+IF(M4="",0,1)+IF(O4="",0,1)+IF(Q4="",0,1)+IF(S4="",0,1) | G4: Button | H4: one Choice | I4: ja | J4: V400 | K4: nein | L4: V400
A5: Vorversicherung | B5: V400 | C5: ja | D5: Waren Sie in den letzten 12 Monaten in einer ausländischen innerhalb der EU, der Schweiz, Norwegen, Grosss-Britanien, Ex Jugoslawien GKV versichert | E5: =I5&IF(K5="","",";"&K5)&IF(M5="","",";"&M5)&IF(O5="","",";"&O5)&IF(Q5="","",";"&Q5)&IF(T5="","",";"&T5) | F5: =IF(I5="",0,1)+IF(K5="",0,1)+IF(M5="",0,1)+IF(O5="",0,1)+IF(Q5="",0,1)+IF(S5="",0,1) | G5: Button | H5: one Choice | I5: ja | J5: A500 | K5: nein | L5: A500
A6: Alter | B6: A500 | C6: jünger als 55 Jahre | D6: Wie alt sind Sie aktuell | E6: =I6&IF(K6="","",";"&K6)&IF(M6="","",";"&M6)&IF(O6="","",";"&O6)&IF(Q6="","",";"&Q6)&IF(T6="","",";"&T6) | F6: =IF(I6="",0,1)+IF(K6="",0,1)+IF(M6="",0,1)+IF(O6="",0,1)+IF(Q6="",0,1)+IF(S6="",0,1) | G6: Button | H6: one Choice | I6: jünger als 55 Jahre | J6: F600 | K6: älter als 54 Jahre | L6: F600
A7: Familienstand | B7: F600 | C7: ja | D7: Sind Sie zurzeit verheiratet | E7: =I7&IF(K7="","",";"&K7)&IF(M7="","",";"&M7)&IF(O7="","",";"&O7)&IF(Q7="","",";"&Q7)&IF(T7="","",";"&T7) | F7: =IF(I7="",0,1)+IF(K7="",0,1)+IF(M7="",0,1)+IF(O7="",0,1)+IF(Q7="",0,1)+IF(S7="",0,1) | G7: Button | H7: one Choice | I7: ja | J7: F720 | K7: nein | L7: F710
A8: Familienstand | B8: F710 | D8: Beabsichtigen Sie in naher Zukunft zu heiraten ? | E8: =I8&IF(K8="","",";"&K8)&IF(M8="","",";"&M8)&IF(O8="","",";"&O8)&IF(Q8="","",";"&Q8)&IF(T8="","",";"&T8) | F8: =IF(I8="",0,1)+IF(K8="",0,1)+IF(M8="",0,1)+IF(O8="",0,1)+IF(Q8="",0,1)+IF(S8="",0,1) | G8: Button | H8: one Choice | I8: ja | J8: F721 | K8: nein | L8: B900
A9: Familienstand | B9: F720 | C9: GKV | D9: Wie ist Ihr Ehepartner zuzeit versichert? | E9: =I9&IF(K9="","",";"&K9)&IF(M9="","",";"&M9)&IF(O9="","",";"&O9)&IF(Q9="","",";"&Q9)&IF(T9="","",";"&T9) | F9: =IF(I9="",0,1)+IF(K9="",0,1)+IF(M9="",0,1)+IF(O9="",0,1)+IF(Q9="",0,1)+IF(S9="",0,1) | G9: Button | H9: one Choice | I9: GKV | J9: F800 | K9: PKV | L9: F800 | M9: ausländische KV | N9: F800 | O9: unversichert | P9: F800 | Q9: anderweitig | R9: F800
A10: Familienstand | B10: F721 | D10: Wie ist Ihr möglicher Ehepartner zuzeit versichert? | E10: =I10&IF(K10="","",";"&K10)&IF(M10="","",";"&M10)&IF(O10="","",";"&O10)&IF(Q10="","",";"&Q10)&IF(T10="","",";"&T10) | F10: =IF(I10="",0,1)+IF(K10="",0,1)+IF(M10="",0,1)+IF(O10="",0,1)+IF(Q10="",0,1)+IF(S10="",0,1) | G10: Button | H10: one Choice | I10: GKV | J10: F800 | K10: PKV | L10: F800 | M10: ausländische KV | N10: F800 | O10: unversichert | P10: F800 | Q10: anderweitig | R10: F800
A11: Familienstand | B11: F800 | C11: Arbeitslos | D11: Was macht ihr Ehepartner beruflich | E11: =I11&IF(K11="","",";"&K11)&IF(M11="","",";"&M11)&IF(O11="","",";"&O11)&IF(Q11="","",";"&Q11)&IF(T11="","",";"&T11) | F11: =IF(I11="",0,1)+IF(K11="",0,1)+IF(M11="",0,1)+IF(O11="",0,1)+IF(Q11="",0,1)+IF(S11="",0,1) | G11: Button | H11: multiple Choice | I11: Angestellter | J11: B900 | K11: Selbstständig | L11: B900 | M11: Beamter | N11: B900 | O11: Landwirt | P11: B900 | Q11: Arbeitslos | R11: B900 | S11: Sonstiges | T11: B900
A12: Beruf | B12: B900 | C12: ja | D12: Sie sind zurzeit Angestellt tätig? | E12: =I12&IF(K12="","",";"&K12)&IF(M12="","",";"&M12)&IF(O12="","",";"&O12)&IF(Q12="","",";"&Q12)&IF(T12="","",";"&T12) | F12: =IF(I12="",0,1)+IF(K12="",0,1)+IF(M12="",0,1)+IF(O12="",0,1)+IF(Q12="",0,1)+IF(S12="",0,1) | G12: Button | H12: one Choice | I12: ja | J12: B1000 | K12: nein | L12: B1000
A13: Beruf | B13: B1000 | C13: ja | D13: sie sind zurzeit selbsttändig tätig? | E13: =I13&IF(K13="","",";"&K13)&IF(M13="","",";"&M13)&IF(O13="","",";"&O13)&IF(Q13="","",";"&Q13)&IF(T13="","",";"&T13) | F13: =IF(I13="",0,1)+IF(K13="",0,1)+IF(M13="",0,1)+IF(O13="",0,1)+IF(Q13="",0,1)+IF(S13="",0,1) | G13: Button | H13: one Choice | I13: ja | J13: B1010 | K13: nein | L13: B1100
A14: Beruf | B14: B1010 | C14: ja | D14: Sie beschäfigen Angestellte? | E14: =I14&IF(K14="","",";"&K14)&IF(M14="","",";"&M14)&IF(O14="","",";"&O14)&IF(Q14="","",";"&Q14)&IF(T14="","",";"&T14) | F14: =IF(I14="",0,1)+IF(K14="",0,1)+IF(M14="",0,1)+IF(O14="",0,1)+IF(Q14="",0,1)+IF(S14="",0,1) | G14: Button | H14: one Choice | I14: ja | J14: B1011 | K14: nein | L14: B1020
A15: Beruf | B15: B1011 | C15: ja | D15: Verdienen alle Angestellten zusammen mehr als die Minijobgrenze | E15: =I15&IF(K15="","",";"&K15)&IF(M15="","",";"&M15)&IF(O15="","",";"&O15)&IF(Q15="","",";"&Q15)&IF(T15="","",";"&T15) | F15: =IF(I15="",0,1)+IF(K15="",0,1)+IF(M15="",0,1)+IF(O15="",0,1)+IF(Q15="",0,1)+IF(S15="",0,1) | G15: Button | H15: one Choice | I15: ja | J15: B1020 | K15: nein | L15: B1020
A16: Beruf | B16: B1020 | C16: bis 20 | D16: Wieviele Wochenstuden arbeiten Sie als Selbstständiger | E16: =I16&IF(K16="","",";"&K16)&IF(M16="","",";"&M16)&IF(O16="","",";"&O16)&IF(Q16="","",";"&Q16)&IF(T16="","",";"&T16) | F16: =IF(I16="",0,1)+IF(K16="",0,1)+IF(M16="",0,1)+IF(O16="",0,1)+IF(Q16="",0,1)+IF(S16="",0,1) | G16: Button | H16: one Choice | I16: bis 20 | J16: B1100 | K16: bis 30 | L16: B1100 | M16: über 30 | N16: B1100
A17: Beruf | B17: B1100 | C17: ja | D17: Sind Sie Beamter | E17: =I17&IF(K17="","",";"&K17)&IF(M17="","",";"&M17)&IF(O17="","",";"&O17)&IF(Q17="","",";"&Q17)&IF(T17="","",";"&T17) | F17: =IF(I17="",0,1)+IF(K17="",0,1)+IF(M17="",0,1)+IF(O17="",0,1)+IF(Q17="",0,1)+IF(S17="",0,1) | G17: Button | H17: one Choice | I17: ja | J17: B1200 | K17: nein | L17: B1200
A18: Beruf | B18: B1200 | C18: ja | D18: Sind Sie Landwirt | E18: =I18&IF(K18="","",";"&K18)&IF(M18="","",";"&M18)&IF(O18="","",";"&O18)&IF(Q18="","",";"&Q18)&IF(T18="","",";"&T18) | F18: =IF(I18="",0,1)+IF(K18="",0,1)+IF(M18="",0,1)+IF(O18="",0,1)+IF(Q18="",0,1)+IF(S18="",0,1) | G18: Button | H18: one Choice | I18: ja | J18: K1 | K18: nein | L18: K1
A19: Kinder | B19: K1 | C19: 0 | D19: Wieviel leibliche Kinder haben sie gezeugt, auch wenn diese schon gestorben sind oder nicht mehr bei den Eltern leben? | E19: =I19&IF(K19="","",";"&K19)&IF(M19="","",";"&M19)&IF(O19="","",";"&O19)&IF(Q19="","",";"&Q19)&IF(T19="","",";"&T19) | F19: =IF(I19="",0,1)+IF(K19="",0,1)+IF(M19="",0,1)+IF(O19="",0,1)+IF(Q19="",0,1)+IF(S19="",0,1) | G19: Eingabefeld | H19: Ganze Zahl | J19: K2
A20: Kinder | B20: K2 | C20: 0 | D20: Wieviel Pflegekinder haben Sie betreut , auch wenn diese schon gestorben sind oder nicht mehr bei den Eltern leben? | E20: =I20&IF(K20="","",";"&K20)&IF(M20="","",";"&M20)&IF(O20="","",";"&O20)&IF(Q20="","",";"&Q20)&IF(T20="","",";"&T20) | F20: =IF(I20="",0,1)+IF(K20="",0,1)+IF(M20="",0,1)+IF(O20="",0,1)+IF(Q20="",0,1)+IF(S20="",0,1) | G20: Eingabefeld | H20: Ganze Zahl | J20: K3
A21: Kinder | B21: K3 | C21: 0 | D21: Wieviele Stiefkinder oder adoptierte Kinder? | E21: =I21&IF(K21="","",";"&K21)&IF(M21="","",";"&M21)&IF(O21="","",";"&O21)&IF(Q21="","",";"&Q21)&IF(T21="","",";"&T21) | F21: =IF(I21="",0,1)+IF(K21="",0,1)+IF(M21="",0,1)+IF(O21="",0,1)+IF(Q21="",0,1)+IF(S21="",0,1) | G21: Eingabefeld | H21: Ganze Zahl | J21: K4
A22: Kinder | B22: K4 | C22: 0 | D22: Bei wieviel Kindern sind Sie im Rahmen der Kinderbetreuung zu Hause geblieben | F22: =IF(I22="",0,1)+IF(K22="",0,1)+IF(M22="",0,1)+IF(O22="",0,1)+IF(Q22="",0,1)+IF(S22="",0,1) | G22: Eingabefeld | H22: Ganze Zahl | J22: E1
A23: Einnahmen | B23: E1 | C23: 0 | D23: Einnahmen aus sozialversicherungspflichtiger Tätigkeit, brutto im Monat | E23: =I23&IF(K23="","",";"&K23)&IF(M23="","",";"&M23)&IF(O23="","",";"&O23)&IF(Q23="","",";"&Q23)&IF(T23="","",";"&T23) | F23: =IF(I23="",0,1)+IF(K23="",0,1)+IF(M23="",0,1)+IF(O23="",0,1)+IF(Q23="",0,1)+IF(S23="",0,1) | G23: Eingabefeld | H23: EUR | J23: E2
A24: Einnahmen | B24: E2 | C24: 0 | D24: Einnahmen aus einem Mini-Job pro Monat | E24: =I24&IF(K24="","",";"&K24)&IF(M24="","",";"&M24)&IF(O24="","",";"&O24)&IF(Q24="","",";"&Q24)&IF(T24="","",";"&T24) | F24: =IF(I24="",0,1)+IF(K24="",0,1)+IF(M24="",0,1)+IF(O24="",0,1)+IF(Q24="",0,1)+IF(S24="",0,1) | G24: Eingabefeld | H24: EUR | J24: E3
A25: Einnahmen | B25: E3 | C25: 1000 | D25: Gewinn aus selbstständiger Tätigkeit pro Monat (gemäß letztem Einkommenssteuerbescheid). Verluste mit minus eintragen. | E25: =I25&IF(K25="","",";"&K25)&IF(M25="","",";"&M25)&IF(O25="","",";"&O25)&IF(Q25="","",";"&Q25)&IF(T25="","",";"&T25) | F25: =IF(I25="",0,1)+IF(K25="",0,1)+IF(M25="",0,1)+IF(O25="",0,1)+IF(Q25="",0,1)+IF(S25="",0,1) | G25: Eingabefeld | H25: EUR | J25: E4
A26: Einnahmen | B26: E4 | C26: 0 | D26: Gewinn aus Vermietung & Verpachtung (gemäß letztem Einkommenssteuerbescheid). Verluste mit minus eintragen. | E26: =I26&IF(K26="","",";"&K26)&IF(M26="","",";"&M26)&IF(O26="","",";"&O26)&IF(Q26="","",";"&Q26)&IF(T26="","",";"&T26) | F26: =IF(I26="",0,1)+IF(K26="",0,1)+IF(M26="",0,1)+IF(O26="",0,1)+IF(Q26="",0,1)+IF(S26="",0,1) | G26: Eingabefeld | H26: EUR | J26: E5
A27: Einnahmen | B27: E5 | C27: 0 | D27: Gewinn aus Kapitalerträgen (gemäß letztem Einkommenssteuerbescheid). Verluste mit minus eintragen. | E27: =I27&IF(K27="","",";"&K27)&IF(M27="","",";"&M27)&IF(O27="","",";"&O27)&IF(Q27="","",";"&Q27)&IF(T27="","",";"&T27) | F27: =IF(I27="",0,1)+IF(K27="",0,1)+IF(M27="",0,1)+IF(O27="",0,1)+IF(Q27="",0,1)+IF(S27="",0,1) | G27: Eingabefeld | H27: EUR | J27: E55
A28: Einnahmen | B28: E55 | C28: 0 | D28: Altersrente der deutschen Rentenversicherung ohne KV-Zuschuss | F28: =IF(I28="",0,1)+IF(K28="",0,1)+IF(M28="",0,1)+IF(O28="",0,1)+IF(Q28="",0,1)+IF(S28="",0,1) | G28: Eingabefeld | H28: EUR | J28: E56
A29: Einnahmen | B29: E56 | C29: 0 | D29: Altersrente aus einem Versorgungswerk | F29: =IF(I29="",0,1)+IF(K29="",0,1)+IF(M29="",0,1)+IF(O29="",0,1)+IF(Q29="",0,1)+IF(S29="",0,1) | G29: Eingabefeld | H29: EUR | J29: E6
A30: Einnahmen | B30: E6 | C30: 0 | D30: Betriebsrente pro Monat | E30: =I30&IF(K30="","",";"&K30)&IF(M30="","",";"&M30)&IF(O30="","",";"&O30)&IF(Q30="","",";"&Q30)&IF(T30="","",";"&T30) | F30: =IF(I30="",0,1)+IF(K30="",0,1)+IF(M30="",0,1)+IF(O30="",0,1)+IF(Q30="",0,1)+IF(S30="",0,1) | G30: Eingabefeld | H30: EUR | J30: E7
A31: Einnahmen | B31: E7 | C31: 0 | D31: Staatlich geförderte Rente pro Monat | E31: =I31&IF(K31="","",";"&K31)&IF(M31="","",";"&M31)&IF(O31="","",";"&O31)&IF(Q31="","",";"&Q31)&IF(T31="","",";"&T31) | F31: =IF(I31="",0,1)+IF(K31="",0,1)+IF(M31="",0,1)+IF(O31="",0,1)+IF(Q31="",0,1)+IF(S31="",0,1) | G31: Eingabefeld | H31: EUR | J31: E8
A32: Einnahmen | B32: E8 | C32: 0 | D32: Private Rente pro Monat | E32: =I32&IF(K32="","",";"&K32)&IF(M32="","",";"&M32)&IF(O32="","",";"&O32)&IF(Q32="","",";"&Q32)&IF(T32="","",";"&T32) | F32: =IF(I32="",0,1)+IF(K32="",0,1)+IF(M32="",0,1)+IF(O32="",0,1)+IF(Q32="",0,1)+IF(S32="",0,1) | G32: Eingabefeld | H32: EUR | J32: E9
A33: Einnahmen | B33: E9 | C33: 0 | D33: Sonstige Einkünfte pro Monat | E33: =I33&IF(K33="","",";"&K33)&IF(M33="","",";"&M33)&IF(O33="","",";"&O33)&IF(Q33="","",";"&Q33)&IF(T33="","",";"&T33) | F33: =IF(I33="",0,1)+IF(K33="",0,1)+IF(M33="",0,1)+IF(O33="",0,1)+IF(Q33="",0,1)+IF(S33="",0,1) | G33: Eingabefeld | H33: EUR | J33: E10
A34: Einnahmen | B34: E10 | C34: ja | D34: Beziehen Sie Bürgergeld? | E34: =I34&IF(K34="","",";"&K34)&IF(M34="","",";"&M34)&IF(O34="","",";"&O34)&IF(Q34="","",";"&Q34)&IF(T34="","",";"&T34) | F34: =IF(I34="",0,1)+IF(K34="",0,1)+IF(M34="",0,1)+IF(O34="",0,1)+IF(Q34="",0,1)+IF(S34="",0,1) | G34: Button | H34: one Choice | I34: ja | J34: E11 | K34: ja
A35: Einnahmen | B35: E11 | C35: ja | D35: Beziehen Sie Grundsicherung? | E35: =I35&IF(K35="","",";"&K35)&IF(M35="","",";"&M35)&IF(O35="","",";"&O35)&IF(Q35="","",";"&Q35)&IF(T35="","",";"&T35) | F35: =IF(I35="",0,1)+IF(K35="",0,1)+IF(M35="",0,1)+IF(O35="",0,1)+IF(Q35="",0,1)+IF(S35="",0,1) | G35: Button | H35: one Choice | I35: ja | J35: Ende | K35: nein | L35: Ende
A36: ungeklärter Status | B36: U1 | D36: Letzte Krankenversicherung nach dem 01.04.2007 im Geltungsbereich Deutschland (inkl. Entsendungen) in der GKV | E36: =I36&IF(K36="","",";"&K36)&IF(M36="","",";"&M36)&IF(O36="","",";"&O36)&IF(Q36="","",";"&Q36)&IF(T36="","",";"&T36) | F36: =IF(I36="",0,1)+IF(K36="",0,1)+IF(M36="",0,1)+IF(O36="",0,1)+IF(Q36="",0,1)+IF(S36="",0,1) | G36: Button | H36: one Choice | I36: ja | J36: V200 | K36: nein | L36: U2
A37: ungeklärter Status | B37: U2 | D37: Letzte Krankenversicherung nach dem 01.04.2007 im Geltungsbereich Deutschland (inkl. Entsendungen) in der PKV | E37: =I37&IF(K37="","",";"&K37)&IF(M37="","",";"&M37)&IF(O37="","",";"&O37)&IF(Q37="","",";"&Q37)&IF(T37="","",";"&T37) | F37: =IF(I37="",0,1)+IF(K37="",0,1)+IF(M37="",0,1)+IF(O37="",0,1)+IF(Q37="",0,1)+IF(S37="",0,1) | G37: Button | H37: one Choice | I37: ja | J37: V200 | K37: nein | L37: U3
A38: ungeklärter Status | B38: U3 | D38: Letzte Krankenversicherung nach dem 01.04.2007 in der EU//EWR/Schweiz/GB/Mazedonien/Türkei oder Tunesien in einer staatlichen KV | E38: =I38&IF(K38="","",";"&K38)&IF(M38="","",";"&M38)&IF(O38="","",";"&O38)&IF(Q38="","",";"&Q38)&IF(T38="","",";"&T38) | F38: =IF(I38="",0,1)+IF(K38="",0,1)+IF(M38="",0,1)+IF(O38="",0,1)+IF(Q38="",0,1)+IF(S38="",0,1) | G38: Button | H38: one Choice | I38: ja | J38: V200 | K38: nein | L38: U4
A39: ungeklärter Status | B39: U4 | D39: Letzte Krankenversicherung nach dem 01.04.2007 in der EU//EWR/Schweiz/GB/Mazedonien/Türkei oder Tunesien in einer privaten KV | E39: =I39&IF(K39="","",";"&K39)&IF(M39="","",";"&M39)&IF(O39="","",";"&O39)&IF(Q39="","",";"&Q39)&IF(T39="","",";"&T39) | F39: =IF(I39="",0,1)+IF(K39="",0,1)+IF(M39="",0,1)+IF(O39="",0,1)+IF(Q39="",0,1)+IF(S39="",0,1) | G39: Button | H39: one Choice | I39: ja | J39: V200 | K39: nein | L39: U5
A40: ungeklärter Status | B40: U5 | D40: Am 1.4.2007 in Deutschland gelebt seit dem in BRD ohne GKV oder PKV-Vorversicherung und an diesem Tag in Deutschland versicherungsfrei im Sinne SGB V § 6 (1+2) gewesen | E40: =I40&IF(K40="","",";"&K40)&IF(M40="","",";"&M40)&IF(O40="","",";"&O40)&IF(Q40="","",";"&Q40)&IF(T40="","",";"&T40) | F40: =IF(I40="",0,1)+IF(K40="",0,1)+IF(M40="",0,1)+IF(O40="",0,1)+IF(Q40="",0,1)+IF(S40="",0,1) | G40: Button | H40: one Choice | I40: ja | J40: V200 | K40: nein | L40: U6
...

Sheet Tabelle2
A1: Einnahmen | B1: Ergebnisse | C1: Fami Normal | D1: Fami mit Mini Job | E1: Best Case | F1: Teilrente Best Case
A2: =Tabelle1!D23 | B2: =Tabelle1!C23 | C2: =B2 | D2: =C2 | E2: 0 | F2: =C2
A3: =Tabelle1!D24 | B3: =Tabelle1!C24 | C3: =B3 | D3: =C3 | E3: 0 | F3: =C3
A4: =Tabelle1!D25 | B4: =Tabelle1!C25 | C4: =B4 | D4: =C4 | E4: =MIN(C4,0) | F4: =C4
A5: =Tabelle1!D26 | B5: =Tabelle1!C26 | C5: =B5 | D5: =C5 | E5: =MIN(C5,0) | F5: =C5
A6: =Tabelle1!D27 | B6: =Tabelle1!C27 | C6: =B6 | D6: =C6 | E6: =MAX(C6,0) | F6: =C6
A7: =Tabelle1!D28 | B7: =Tabelle1!C28 | C7: =IF(B7>0,B7+C15,0) | D7: =C7 | E7: =MAX(C7,0) | F7: =C7*0.1
A8: =Tabelle1!D29 | B8: =Tabelle1!C29 | C8: =B8 | D8: =C8 | E8: =MAX(C8,0) | F8: =C8
A9: =Tabelle1!D30 | B9: =Tabelle1!C30 | C9: =B9 | D9: =C9 | E9: =MAX(C9,0) | F9: =C9
A10: =Tabelle1!D31 | B10: =Tabelle1!C31 | C10: =B10 | D10: =C10 | E10: =MAX(C10,0) | F10: =C10
A11: =Tabelle1!D32 | B11: =Tabelle1!C32 | C11: =B11 | D11: =C11 | E11: =MAX(C11,0) | F11: =C11
A12: =Tabelle1!D33 | B12: =Tabelle1!C33 | C12: =B12 | D12: =C12 | E12: =MAX(C12,0) | F12: =C12
C14: =SUM(C2:C15) | D14: =SUM(D2:D13) | E14: =C14 | F14: =C14
A15: Kindererziehung Anzahl der Kinder | B15: =Tabelle1!C22 | C15: =B15*Tabelle3!B1*2.5*-1 | D15: =C15 | E15: =D15 | F15: =E15
A16: =Tabelle1!D7 | B16: =Tabelle1!C7
A17: =Tabelle1!D8 | B17: =Tabelle1!C8
A18: =Tabelle1!D34 | B18: =Tabelle1!C35 | C18: =B18
A19: =Tabelle1!D35 | B19: =Tabelle1!C34 | C19: =B19
A21: Fami möglich | C21: =IF(C14<Tabelle3!$B5,"ja","nein") | D21: =IF(D14<Tabelle3!$B5,"ja","nein") | E21: =IF(E14<Tabelle3!$B5,"ja","nein") | F21: =IF(F14<Tabelle3!$B5,"ja","nein")
A22: Ergebnis | C22: =IF(C21="ja",1,0)

Sheet Tabelle4
A1: Ergebnis | B1: 1
A2: Beschreibung | B2: 2
A3: Empfehlung | B3: 3

Sheet Tabelle3
A1: Entgeltpunkt | B1: 40 | D1: ja
A2: 1/7 Bezugsgröße | B2: 565 | D2: nein
A3: Mini Job | B3: 603
A5: Grenze | B5: =IF(Tabelle1!C24>0,Tabelle3!B3,Tabelle3!B2)
